Workbook

Sheet Raw Data
A1: Sample Retail Co - Historicals & Assumptions (₹ millions)
A6: A. Historical Income Statement | B6: FY2023 | C6: FY2024 | D6: FY2025
A7: Revenue | B7: =5000*$B$58 -> 479350 | C7: =5600*$B$58 -> 536872 | D7: =6270*$B$58 -> 601104.9
A8: COGS | B8: =3000*$B$58 -> 287610 | C8: =3360*$B$58 -> 322123.2 | D8: =3762*$B$58 -> 360662.94
A9: Gross Profit | B9: =2000*$B$58 -> 191740 | C9: =2240*$B$58 -> 214748.8 | D9: =2508*$B$58 -> 240441.96
A10: SG&A | B10: =1000*$B$58 -> 95870 | C10: =1120*$B$58 -> 107374.4 | D10: =1254*$B$58 -> 120220.98
A11: EBITDA | B11: =1000*$B$58 -> 95870 | C11: =1120*$B$58 -> 107374.4 | D11: =1254*$B$58 -> 120220.98
A12: D&A | B12: =150*$B$58 -> 14380.5 | C12: =165*$B$58 -> 15818.55 | D12: =180*$B$58 -> 17256.6
A13: EBIT | B13: =850*$B$58 -> 81489.5 | C13: =955*$B$58 -> 91555.85 | D13: =1074*$B$58 -> 102964.38
A14: Interest Expense | B14: =80*$B$58 -> 7669.6 | C14: =85*$B$58 -> 8148.95 | D14: =90*$B$58 -> 8628.3
A15: EBT | B15: =770*$B$58 -> 73819.9 | C15: =870*$B$58 -> 83406.9 | D15: =984*$B$58 -> 94336.08
A16: Tax (25%) | B16: =192.5*$B$58 -> 18454.975 | C16: =217.5*$B$58 -> 20851.725 | D16: =246*$B$58 -> 23584.02
A17: Net Income | B17: =577.5*$B$58 -> 55364.925 | C17: =652.5*$B$58 -> 62555.175 | D17: =738*$B$58 -> 70752.06
A20: B. Opening Balance Sheet - as of FY 2025 year-end | B20: FY2025
A21: Cash | B21: =450*$B$58 -> 43141.5
A22: Accounts Receivable | B22: =770*$B$58 -> 73819.9
A23: Inventory | B23: =410*$B$58 -> 39306.7
A24: Other Current Assets | B24: =120*$B$58 -> 11504.4
A25: Total Current Assets | B25: =1750*$B$58 -> 167772.5
A26: PP&E, Gross | B26: =2800*$B$58 -> 268436
A27: Accumulated Depreciation | B27: =900*$B$58 -> 86283
A28: PP&E, Net | B28: =1900*$B$58 -> 182153
A29: Total Assets | B29: =3650*$B$58 -> 349925.5
A30: Accounts Payable | B30: =360*$B$58 -> 34513.2
A31: Short-term Debt | B31: =200*$B$58 -> 19174
A32: Other Current Liabilities | B32: =150*$B$58 -> 14380.5
A33: Total Current Liabilities | B33: =710*$B$58 -> 68067.7
A34: Long-term Debt | B34: =900*$B$58 -> 86283
A35: Total Liabilities | B35: =1610*$B$58 -> 154350.7
A36: Common Stock | B36: =500*$B$58 -> 47935
A37: Retained Earnings | B37: =1540*$B$58 -> 147639.8
A38: Total Equity | B38: =2040*$B$58 -> 195574.8
A39: Total Liabilities + Equity (check) | B39: =3650*$B$58 -> 349925.5
A41: C. Projection Assumptions (FY2026E - FY2030E)
A42: Revenue Growth % | B42: 0.12
A43: COGS % of Revenue | B43: 0.6
A44: SG&A % of Revenue | B44: 0.2
A45: D&A % of Revenue | B45: 0.03
A46: CapEx % of Revenue | B46: 0.06
A47: Tax Rate | B47: 0.25
...

Sheet Schedules
A1: Supporting Schedules — projected (₹ millions)
A6: 1. WORKING CAPITAL SCHEDULE | B6: FY2026E | C6: FY2027E | D6: FY2028E | E6: FY2029E | F6: FY2030E
A7: Revenue (link from Income Statement) | B7: ='Income Statement'!E6 -> 673237.49 | C7: ='Income Statement'!F6 -> 754025.99 | D7: ='Income Statement'!G6 -> 844509.1 | E7: ='Income Statement'!H6 -> 945850.2 | F7: ='Income Statement'!I6 -> 1059352.2
A8: COGS (link from Income Statement) | B8: ='Income Statement'!E7 -> 403942.49 | C8: ='Income Statement'!F7 -> 452415.59 | D8: ='Income Statement'!G7 -> 506705.46 | E8: ='Income Statement'!H7 -> 567510.12 | F8: ='Income Statement'!I7 -> 635611.33
A9: Accounts Receivable = Revenue/365 x DSO | B9: =B7/365*'Raw Data'!$B$49 -> 83001.882 | C9: =C7/365*'Raw Data'!$B$49 -> 92962.108 | D9: =D7/365*'Raw Data'!$B$49 -> 104117.56 | E9: =E7/365*'Raw Data'!$B$49 -> 116611.67 | F9: =F7/365*'Raw Data'!$B$49 -> 130605.07
A10: Inventory = COGS/365 x DIO | B10: =B8/365*'Raw Data'!$B$50 -> 44267.67 | C10: =C8/365*'Raw Data'!$B$50 -> 49579.791 | D10: =D8/365*'Raw Data'!$B$50 -> 55529.366 | E10: =E8/365*'Raw Data'!$B$50 -> 62192.89 | F10: =F8/365*'Raw Data'!$B$50 -> 69656.036
A11: Accounts Payable = COGS/365 x DPO | B11: =B8/365*'Raw Data'!$B$51 -> 38734.212 | C11: =C8/365*'Raw Data'!$B$51 -> 43382.317 | D11: =D8/365*'Raw Data'!$B$51 -> 48588.195 | E11: =E8/365*'Raw Data'!$B$51 -> 54418.778 | F11: =F8/365*'Raw Data'!$B$51 -> 60949.032
A14: 2. PP&E ROLL-FORWARD | B14: FY2026E | C14: FY2027E | D14: FY2028E | E14: FY2029E | F14: FY2030E
A15: Beginning PP&E, Gross | B15: ='Balance Sheet'!B11 -> 268436 | C15: =B17 -> 308830.25 | D15: =C17 -> 354071.81 | E15: =D17 -> 404742.35 | F15: =E17 -> 461493.37
A16: Add: CapEx | B16: ='Income Statement'!E6*'Raw Data'!$B$46 -> 40394.249 | C16: ='Income Statement'!F6*'Raw Data'!$B$46 -> 45241.559 | D16: ='Income Statement'!G6*'Raw Data'!$B$46 -> 50670.546 | E16: ='Income Statement'!H6*'Raw Data'!$B$46 -> 56751.012 | F16: ='Income Statement'!I6*'Raw Data'!$B$46 -> 63561.133
A17: Ending PP&E, Gross | B17: =B15+B16 -> 308830.25 | C17: =C15+C16 -> 354071.81 | D17: =D15+D16 -> 404742.35 | E17: =E15+E16 -> 461493.37 | F17: =F15+F16 -> 525054.5
A18: Beginning Accumulated Depreciation | B18: ='Balance Sheet'!B12 -> 86283 | C18: =B20 -> 106480.12 | D18: =C20 -> 129100.9 | E18: =D20 -> 154436.18 | F18: =E20 -> 182811.68
A19: Add: D&A | B19: ='Income Statement'!E11 -> 20197.125 | C19: ='Income Statement'!F11 -> 22620.78 | D19: ='Income Statement'!G11 -> 25335.273 | E19: ='Income Statement'!H11 -> 28375.506 | F19: ='Income Statement'!I11 -> 31780.567
A20: Ending Accumulated Depreciation | B20: =B18+B19 -> 106480.12 | C20: =C18+C19 -> 129100.9 | D20: =D18+D19 -> 154436.18 | E20: =E18+E19 -> 182811.68 | F20: =F18+F19 -> 214592.25
A21: Ending PP&E, Net | B21: =B17-B20 -> 202350.12 | C21: =C17-C20 -> 224970.9 | D21: =D17-D20 -> 250306.18 | E21: =E17-E20 -> 278681.68 | F21: =F17-F20 -> 310462.25
A24: 3. DEBT SCHEDULE | B24: FY2026E | C24: FY2027E | D24: FY2028E | E24: FY2029E | F24: FY2030E
A25: Beginning Total Debt (ST + LT) | B25: ='Balance Sheet'!B16+'Balance Sheet'!B19 -> 105457 | C25: =B28 -> 105457 | D25: =C28 -> 105457 | E25: =D28 -> 105457 | F25: =E28 -> 105457
A26: Add: New Debt Issued | B26: =0 -> 0 | C26: =0 -> 0 | D26: =0 -> 0 | E26: =0 -> 0 | F26: =0 -> 0
A27: Less: Debt Repaid | B27: =0 -> 0 | C27: =0 -> 0 | D27: =0 -> 0 | E27: =0 -> 0 | F27: =0 -> 0
A28: Ending Total Debt | B28: =B25+B26-B27 -> 105457 | C28: =C25+C26-C27 -> 105457 | D28: =D25+D26-D27 -> 105457 | E28: =E25+E26-E27 -> 105457 | F28: =F25+F26-F27 -> 105457
A29: Interest Expense = Beginning Debt x Rate | B29: =B25*'Raw Data'!$B$48 -> 9491.13 | C29: =C25*'Raw Data'!$B$48 -> 9491.13 | D29: =D25*'Raw Data'!$B$48 -> 9491.13 | E29: =E25*'Raw Data'!$B$48 -> 9491.13 | F29: =F25*'Raw Data'!$B$48 -> 9491.13

Sheet Income Statement
A1: Income Statement - historical + projection (₹ millions)
B5: FY2023 | C5: FY2024 | D5: FY2025 | E5: FY2026E | F5: FY2027E | G5: FY2028E | H5: FY2029E | I5: FY2030E
A6: Revenue | B6: ='Raw Data'!B7 -> 479350 | C6: ='Raw Data'!C7 -> 536872 | D6: ='Raw Data'!D7 -> 601104.9 | E6: =D6*(1+'Raw Data'!$B$42) -> 673237.49 | F6: =E6*(1+'Raw Data'!$B$42) -> 754025.99 | G6: =F6*(1+'Raw Data'!$B$42) -> 844509.1 | H6: =G6*(1+'Raw Data'!$B$42) -> 945850.2 | I6: =H6*(1+'Raw Data'!$B$42) -> 1059352.2
A7: COGS | B7: ='Raw Data'!B8 -> 287610 | C7: ='Raw Data'!C8 -> 322123.2 | D7: ='Raw Data'!D8 -> 360662.94 | E7: =E6*'Raw Data'!$B$43 -> 403942.49 | F7: =F6*'Raw Data'!$B$43 -> 452415.59 | G7: =G6*'Raw Data'!$B$43 -> 506705.46 | H7: =H6*'Raw Data'!$B$43 -> 567510.12 | I7: =I6*'Raw Data'!$B$43 -> 635611.33
A8: Gross Profit | B8: ='Raw Data'!B9 -> 191740 | C8: ='Raw Data'!C9 -> 214748.8 | D8: ='Raw Data'!D9 -> 240441.96 | E8: =E6-E7 -> 269295 | F8: =F6-F7 -> 301610.39 | G8: =G6-G7 -> 337803.64 | H8: =H6-H7 -> 378340.08 | I8: =I6-I7 -> 423740.89
A9: SG&A | B9: ='Raw Data'!B10 -> 95870 | C9: ='Raw Data'!C10 -> 107374.4 | D9: ='Raw Data'!D10 -> 120220.98 | E9: =E6*'Raw Data'!$B$44 -> 134647.5 | F9: =F6*'Raw Data'!$B$44 -> 150805.2 | G9: =G6*'Raw Data'!$B$44 -> 168901.82 | H9: =H6*'Raw Data'!$B$44 -> 189170.04 | I9: =I6*'Raw Data'!$B$44 -> 211870.44
A10: EBITDA | B10: ='Raw Data'!B11 -> 95870 | C10: ='Raw Data'!C11 -> 107374.4 | D10: ='Raw Data'!D11 -> 120220.98 | E10: =E8-E9 -> 134647.5 | F10: =F8-F9 -> 150805.2 | G10: =G8-G9 -> 168901.82 | H10: =H8-H9 -> 189170.04 | I10: =I8-I9 -> 211870.44
A11: D&A | B11: ='Raw Data'!B12 -> 14380.5 | C11: ='Raw Data'!C12 -> 15818.55 | D11: ='Raw Data'!D12 -> 17256.6 | E11: =E6*'Raw Data'!$B$45 -> 20197.125 | F11: =F6*'Raw Data'!$B$45 -> 22620.78 | G11: =G6*'Raw Data'!$B$45 -> 25335.273 | H11: =H6*'Raw Data'!$B$45 -> 28375.506 | I11: =I6*'Raw Data'!$B$45 -> 31780.567
A12: EBIT | B12: ='Raw Data'!B13 -> 81489.5 | C12: ='Raw Data'!C13 -> 91555.85 | D12: ='Raw Data'!D13 -> 102964.38 | E12: =E10-E11 -> 114450.37 | F12: =F10-F11 -> 128184.42 | G12: =G10-G11 -> 143566.55 | H12: =H10-H11 -> 160794.53 | I12: =I10-I11 -> 180089.88
A13: Interest Expense | B13: ='Raw Data'!B14 -> 7669.6 | C13: ='Raw Data'!C14 -> 8148.95 | D13: ='Raw Data'!D14 -> 8628.3 | E13: =Schedules!B29 -> 9491.13 | F13: =Schedules!C29 -> 9491.13 | G13: =Schedules!D29 -> 9491.13 | H13: =Schedules!E29 -> 9491.13 | I13: =Schedules!F29 -> 9491.13
A14: EBT | B14: ='Raw Data'!B15 -> 73819.9 | C14: ='Raw Data'!C15 -> 83406.9 | D14: ='Raw Data'!D15 -> 94336.08 | E14: =E12-E13 -> 104959.24 | F14: =F12-F13 -> 118693.29 | G14: =G12-G13 -> 134075.42 | H14: =H12-H13 -> 151303.4 | I14: =I12-I13 -> 170598.75
A15: Tax | B15: ='Raw Data'!B16 -> 18454.975 | C15: ='Raw Data'!C16 -> 20851.725 | D15: ='Raw Data'!D16 -> 23584.02 | E15: =E14*'Raw Data'!$B$47 -> 26239.811 | F15: =F14*'Raw Data'!$B$47 -> 29673.322 | G15: =G14*'Raw Data'!$B$47 -> 33518.854 | H15: =H14*'Raw Data'!$B$47 -> 37825.851 | I15: =I14*'Raw Data'!$B$47 -> 42649.687
A16: Net Income | B16: ='Raw Data'!B17 -> 55364.925 | C16: ='Raw Data'!C17 -> 62555.175 | D16: ='Raw Data'!D17 -> 70752.06 | E16: =E14-E15 -> 78719.432 | F16: =F14-F15 -> 89019.966 | G16: =G14-G15 -> 100556.56 | H16: =H14-H15 -> 113477.55 | I16: =I14-I15 -> 127949.06

Sheet Balance Sheet
A1: Balance Sheet - FY2025 opening + projection (₹ millions)
B5: FY2025 | C5: FY2026E | D5: FY2027E | E5: FY2028E | F5: FY2029E | G5: FY2030E
A6: Cash | B6: ='Raw Data'!B21 -> 43141.5 | C6: ='Cash Flow Statement'!B19 -> 75997.98 | D6: ='Cash Flow Statement'!C19 -> 113968.93 | E6: ='Cash Flow Statement'!D19 -> 157179.76 | F6: ='Cash Flow Statement'!E19 -> 206259.25 | G6: ='Cash Flow Statement'!F19 -> 261911.64
A7: Accounts Receivable | B7: ='Raw Data'!B22 -> 73819.9 | C7: =Schedules!B9 -> 83001.882 | D7: =Schedules!C9 -> 92962.108 | E7: =Schedules!D9 -> 104117.56 | F7: =Schedules!E9 -> 116611.67 | G7: =Schedules!F9 -> 130605.07
A8: Inventory | B8: ='Raw Data'!B23 -> 39306.7 | C8: =Schedules!B10 -> 44267.67 | D8: =Schedules!C10 -> 49579.791 | E8: =Schedules!D10 -> 55529.366 | F8: =Schedules!E10 -> 62192.89 | G8: =Schedules!F10 -> 69656.036
A9: Other Current Assets | B9: ='Raw Data'!B24 -> 11504.4 | C9: =$B9 -> 11504.4 | D9: =C9 -> 11504.4 | E9: =D9 -> 11504.4 | F9: =E9 -> 11504.4 | G9: =F9 -> 11504.4
A10: Total Current Assets | B10: ='Raw Data'!B25 -> 167772.5 | C10: =SUM(C6:C9) -> 214771.93 | D10: =SUM(D6:D9) -> 268015.23 | E10: =SUM(E6:E9) -> 328331.09 | F10: =SUM(F6:F9) -> 396568.21 | G10: =SUM(G6:G9) -> 473677.14
A11: PP&E, Gross | B11: ='Raw Data'!B26 -> 268436 | C11: =Schedules!B17 -> 308830.25 | D11: =Schedules!C17 -> 354071.81 | E11: =Schedules!D17 -> 404742.35 | F11: =Schedules!E17 -> 461493.37 | G11: =Schedules!F17 -> 525054.5
A12: Accumulated Depreciation | B12: ='Raw Data'!B27 -> 86283 | C12: =Schedules!B20 -> 106480.12 | D12: =Schedules!C20 -> 129100.9 | E12: =Schedules!D20 -> 154436.18 | F12: =Schedules!E20 -> 182811.68 | G12: =Schedules!F20 -> 214592.25
A13: PP&E, Net | B13: ='Raw Data'!B28 -> 182153 | C13: =C11-C12 -> 202350.12 | D13: =D11-D12 -> 224970.9 | E13: =E11-E12 -> 250306.18 | F13: =F11-F12 -> 278681.68 | G13: =G11-G12 -> 310462.25
A14: Total Assets | B14: ='Raw Data'!B29 -> 349925.5 | C14: =C10+C13 -> 417122.06 | D14: =D10+D13 -> 492986.14 | E14: =E10+E13 -> 578637.26 | F14: =F10+F13 -> 675249.89 | G14: =G10+G13 -> 784139.39
A15: Accounts Payable | B15: ='Raw Data'!B30 -> 34513.2 | C15: =Schedules!B11 -> 38734.212 | D15: =Schedules!C11 -> 43382.317 | E15: =Schedules!D11 -> 48588.195 | F15: =Schedules!E11 -> 54418.778 | G15: =Schedules!F11 -> 60949.032
A16: Short-term Debt | B16: ='Raw Data'!B31 -> 19174 | C16: =$B16 -> 19174 | D16: =C16 -> 19174 | E16: =D16 -> 19174 | F16: =E16 -> 19174 | G16: =F16 -> 19174
A17: Other Current Liabilities | B17: ='Raw Data'!B32 -> 14380.5 | C17: =$B17 -> 14380.5 | D17: =C17 -> 14380.5 | E17: =D17 -> 14380.5 | F17: =E17 -> 14380.5 | G17: =F17 -> 14380.5
A18: Total Current Liabilities | B18: ='Raw Data'!B33 -> 68067.7 | C18: =SUM(C15:C17) -> 72288.712 | D18: =SUM(D15:D17) -> 76936.817 | E18: =SUM(E15:E17) -> 82142.695 | F18: =SUM(F15:F17) -> 87973.278 | G18: =SUM(G15:G17) -> 94503.532
A19: Long-term Debt | B19: ='Raw Data'!B34 -> 86283 | C19: =$B19 -> 86283 | D19: =C19 -> 86283 | E19: =D19 -> 86283 | F19: =E19 -> 86283 | G19: =F19 -> 86283
A20: Total Liabilities | B20: ='Raw Data'!B35 -> 154350.7 | C20: =C18+C19 -> 158571.71 | D20: =D18+D19 -> 163219.82 | E20: =E18+E19 -> 168425.7 | F20: =F18+F19 -> 174256.28 | G20: =G18+G19 -> 180786.53
A21: Common Stock | B21: ='Raw Data'!B36 -> 47935 | C21: =$B21 -> 47935 | D21: =C21 -> 47935 | E21: =D21 -> 47935 | F21: =E21 -> 47935 | G21: =F21 -> 47935
A22: Retained Earnings | B22: ='Raw Data'!B37 -> 147639.8 | C22: =B22+'Income Statement'!E16-'Cash Flow Statement'!B14 -> 210615.35 | D22: =C22+'Income Statement'!F16-'Cash Flow Statement'!C14 -> 281831.32 | E22: =D22+'Income Statement'!G16-'Cash Flow Statement'!D14 -> 362276.57 | F22: =E22+'Income Statement'!H16-'Cash Flow Statement'!E14 -> 453058.61 | G22: =F22+'Income Statement'!I16-'Cash Flow Statement'!F14 -> 555417.86
A23: Total Equity | B23: ='Raw Data'!B38 -> 195574.8 | C23: =C21+C22 -> 258550.35 | D23: =D21+D22 -> 329766.32 | E23: =E21+E22 -> 410211.57 | F23: =F21+F22 -> 500993.61 | G23: =G21+G22 -> 603352.86
A24: Total Liabilities + Equity | B24: ='Raw Data'!B39 -> 349925.5 | C24: =C20+C23 -> 417122.06 | D24: =D20+D23 -> 492986.14 | E24: =E20+E23 -> 578637.26 | F24: =F20+F23 -> 675249.89 | G24: =G20+G23 -> 784139.39
A25: Check (Assets - (Liab + Equity)) | B25: =B14-B20 -> 195574.8 | C25: =C14-C20 -> 258550.35 | D25: =D14-D20 -> 329766.32 | E25: =E14-E20 -> 410211.57 | F25: =F14-F20 -> 500993.61 | G25: =G14-G20 -> 603352.86

Sheet Cash Flow Statement
A1: Cash Flow Statement — projected (₹ millions)
B5: FY2026E | C5: FY2027E | D5: FY2028E | E5: FY2029E | F5: FY2030E
A6: Net Income | B6: ='Income Statement'!E16 -> 78719.432 | C6: ='Income Statement'!F16 -> 89019.966 | D6: ='Income Statement'!G16 -> 100556.56 | E6: ='Income Statement'!H16 -> 113477.55 | F6: ='Income Statement'!I16 -> 127949.06
A7: Add: D&A | B7: ='Income Statement'!E11 -> 20197.125 | C7: ='Income Statement'!F11 -> 22620.78 | D7: ='Income Statement'!G11 -> 25335.273 | E7: ='Income Statement'!H11 -> 28375.506 | F7: ='Income Statement'!I11 -> 31780.567
A8: Less: Increase in Accounts Receivable | B8: ='Balance Sheet'!C7-'Balance Sheet'!B7 -> 9181.9821 | C8: ='Balance Sheet'!D7-'Balance Sheet'!C7 -> 9960.2258 | D8: ='Balance Sheet'!E7-'Balance Sheet'!D7 -> 11155.453 | E8: ='Balance Sheet'!F7-'Balance Sheet'!E7 -> 12494.107 | F8: ='Balance Sheet'!G7-'Balance Sheet'!F7 -> 13993.4
A9: Less: Increase in Inventory | B9: ='Balance Sheet'!C8-'Balance Sheet'!B8 -> 4960.9704 | C9: ='Balance Sheet'!D8-'Balance Sheet'!C8 -> 5312.1205 | D9: ='Balance Sheet'!E8-'Balance Sheet'!D8 -> 5949.5749 | E9: ='Balance Sheet'!F8-'Balance Sheet'!E8 -> 6663.5239 | F9: ='Balance Sheet'!G8-'Balance Sheet'!F8 -> 7463.1468
A10: Add: Increase in Accounts Payable | B10: ='Balance Sheet'!C15-'Balance Sheet'!B15 -> 4221.0116 | C10: ='Balance Sheet'!D15-'Balance Sheet'!C15 -> 4648.1054 | D10: ='Balance Sheet'!E15-'Balance Sheet'!D15 -> 5205.878 | E10: ='Balance Sheet'!F15-'Balance Sheet'!E15 -> 5830.5834 | F10: ='Balance Sheet'!G15-'Balance Sheet'!F15 -> 6530.2534
A11: Cash Flow from Operations | B11: =B6+B7-B8-B9+B10 -> 88994.616 | C11: =C6+C7-C8-C9+C10 -> 101016.5 | D11: =D6+D7-D8-D9+D10 -> 113992.69 | E11: =E6+E7-E8-E9+E10 -> 128526.01 | F11: =F6+F7-F8-F9+F10 -> 144803.33
A12: Less: CapEx | B12: =Schedules!B16 -> 40394.249 | C12: =Schedules!C16 -> 45241.559 | D12: =Schedules!D16 -> 50670.546 | E12: =Schedules!E16 -> 56751.012 | F12: =Schedules!F16 -> 63561.133
A13: Cash Flow from Investing | B13: =-B12 -> -40394.249 | C13: =-C12 -> -45241.559 | D13: =-D12 -> -50670.546 | E13: =-E12 -> -56751.012 | F13: =-F12 -> -63561.133
A14: Less: Dividends Paid | B14: =B6*'Raw Data'!$B$52 -> 15743.886 | C14: =C6*'Raw Data'!$B$52 -> 17803.993 | D14: =D6*'Raw Data'!$B$52 -> 20111.313 | E14: =E6*'Raw Data'!$B$52 -> 22695.511 | F14: =F6*'Raw Data'!$B$52 -> 25589.812
A15: Add/(Less): Debt Issued/(Repaid) | B15: =Schedules!B26-Schedules!B27 -> 0 | C15: =Schedules!C26-Schedules!C27 -> 0 | D15: =Schedules!D26-Schedules!D27 -> 0 | E15: =Schedules!E26-Schedules!E27 -> 0 | F15: =Schedules!F26-Schedules!F27 -> 0
A16: Cash Flow from Financing | B16: =-B14+B15 -> -15743.886 | C16: =-C14+C15 -> -17803.993 | D16: =-D14+D15 -> -20111.313 | E16: =-E14+E15 -> -22695.511 | F16: =-F14+F15 -> -25589.812
A17: Net Change in Cash | B17: =B11+B13+B16 -> 32856.48 | C17: =C11+C13+C16 -> 37970.952 | D17: =D11+D13+D16 -> 43210.828 | E17: =E11+E13+E16 -> 49079.488 | F17: =F11+F13+F16 -> 55652.388
A18: Add: Beginning Cash | B18: ='Balance Sheet'!B6 -> 43141.5 | C18: ='Balance Sheet'!C6 -> 75997.98 | D18: ='Balance Sheet'!D6 -> 113968.93 | E18: ='Balance Sheet'!E6 -> 157179.76 | F18: ='Balance Sheet'!F6 -> 206259.25
A19: Ending Cash (should tie to Balance Sheet) | B19: =B17+B18 -> 75997.98 | C19: =C17+C18 -> 113968.93 | D19: =D17+D18 -> 157179.76 | E19: =E17+E18 -> 206259.25 | F19: =F17+F18 -> 261911.64
